<?xml version="1.0" ?>
<robot name="diff_robot" xmlns:xacro="http://www.ros.org/wiki/xacro">

<!-- materials file -->
<xacro:include filename="$(find robot_description)/urdf/materials.xacro" />
<!-- gazebo materials file -->
<xacro:include filename="$(find robot_description)/gazebo/robot_gazebo_material.gazebo" />
<!-- transfer -->
<!-- <xacro:include filename="$(find robot_description)/urdf/robot.trans" /> -->
<!-- plugin -->
<xacro:include filename="$(find robot_description)/gazebo/robot_gazebo_plugin.gazebo" />
<xacro:include filename="$(find robot_description)/gazebo/robot.gazebo" />


<link name="base_link">
  <inertial>
    <origin xyz="0.0016414935415674532 0.00013181938023246637 0.0817851117660408" rpy="0 0 0"/>
    <mass value="4.641985935784635"/>
    <inertia ixx="0.017373" iyy="0.036748" izz="0.049678" ixy="-4.2e-05" iyz="-3e-05" ixz="-0.000462"/>
  </inertial>
  <visual>
    <origin xyz="0 0 0" rpy="0 0 0"/>
    <geometry>
      <mesh filename="package://robot_description/meshes/base_link.stl" scale="0.001 0.001 0.001"/>
    </geometry>
    <material name="blue"/>
  </visual>
  <collision>
    <origin xyz="0 0 0" rpy="0 0 0"/>
    <geometry>
      <mesh filename="package://robot_description/meshes/base_link.stl" scale="0.001 0.001 0.001"/>
    </geometry>
  </collision>
</link>

<link name="lidar_1">
  <inertial>
    <origin xyz="0.0 -4.336808689942018e-18 0.015000000000000013" rpy="0 0 0"/>
    <mass value="0.6950302507169375"/>
    <inertia ixx="0.000265" iyy="0.000265" izz="0.000426" ixy="-0.0" iyz="-0.0" ixz="-0.0"/>
  </inertial>
  <visual>
    <origin xyz="-0.07 -0.005 -0.146" rpy="0 0 0"/>
    <geometry>
      <mesh filename="package://robot_description/meshes/lidar_1.stl" scale="0.001 0.001 0.001"/>
    </geometry>
    <material name="blue"/>
  </visual>
  <collision>
    <origin xyz="-0.07 -0.005 -0.146" rpy="0 0 0"/>
    <geometry>
      <mesh filename="package://robot_description/meshes/lidar_1.stl" scale="0.001 0.001 0.001"/>
    </geometry>
  </collision>
</link>

<link name="caster_wheel_1">
  <inertial>
    <origin xyz="1.3877787807814457e-17 1.5790972091241895e-18 -0.02301136363636362" rpy="0 0 0"/>
    <mass value="0.02384828798232877"/>
    <inertia ixx="5e-06" iyy="5e-06" izz="2e-06" ixy="-0.0" iyz="0.0" ixz="-0.0"/>
  </inertial>
  <visual>
    <origin xyz="-0.11 -0.0 -0.05" rpy="0 0 0"/>
    <geometry>
      <mesh filename="package://robot_description/meshes/caster_wheel_1.stl" scale="0.001 0.001 0.001"/>
    </geometry>
    <material name="silver"/>
  </visual>
  <collision>
    <origin xyz="-0.11 -0.0 -0.05" rpy="0 0 0"/>
    <geometry>
      <mesh filename="package://robot_description/meshes/caster_wheel_1.stl" scale="0.001 0.001 0.001"/>
    </geometry>
  </collision>
</link>

<link name="left_wheel_1">
  <inertial>
    <origin xyz="8.923417560424696e-15 0.014858133669609086 2.0816681711721685e-17" rpy="0 0 0"/>
    <mass value="0.07240291144049812"/>
    <inertia ixx="2.4e-05" iyy="4.4e-05" izz="2.4e-05" ixy="0.0" iyz="0.0" ixz="0.0"/>
  </inertial>
  <visual>
    <origin xyz="0.1 -0.095 -0.035" rpy="0 0 0"/>
    <geometry>
      <mesh filename="package://robot_description/meshes/left_wheel_1.stl" scale="0.001 0.001 0.001"/>
    </geometry>
    <material name="orange"/>
  </visual>
  <collision>
    <origin xyz="0.1 -0.095 -0.035" rpy="0 0 0"/>
    <geometry>
      <mesh filename="package://robot_description/meshes/left_wheel_1.stl" scale="0.001 0.001 0.001"/>
    </geometry>
  </collision>
</link>

<link name="right_wheel_1">
  <inertial>
    <origin xyz="3.562428130265971e-14 -0.014858133669609086 -6.938893903907228e-18" rpy="0 0 0"/>
    <mass value="0.07240291144049789"/>
    <inertia ixx="2.4e-05" iyy="4.4e-05" izz="2.4e-05" ixy="0.0" iyz="-0.0" ixz="0.0"/>
  </inertial>
  <visual>
    <origin xyz="0.1 0.095 -0.035" rpy="0 0 0"/>
    <geometry>
      <mesh filename="package://robot_description/meshes/right_wheel_1.stl" scale="0.001 0.001 0.001"/>
    </geometry>
    <material name="orange"/>
  </visual>
  <collision>
    <origin xyz="0.1 0.095 -0.035" rpy="0 0 0"/>
    <geometry>
      <mesh filename="package://robot_description/meshes/right_wheel_1.stl" scale="0.001 0.001 0.001"/>
    </geometry>
  </collision>
</link>

<!-- joint -->
<joint name="to_lidar" type="fixed">
  <origin xyz="0.07 0.005 0.146" rpy="0 0 0"/>
  <parent link="base_link"/>
  <child link="lidar_1"/>
</joint>

<joint name="to_caster_wheel" type="fixed">
  <origin xyz="0.11 0.0 0.05" rpy="0 0 0"/>
  <parent link="base_link"/>
  <child link="caster_wheel_1"/>
</joint>

<joint name="to_left_wheel" type="continuous">
  <origin xyz="-0.1 0.095 0.035" rpy="0 0 0"/>
  <parent link="base_link"/>
  <child link="left_wheel_1"/>
  <axis xyz="0.0 1.0 0.0"/>
</joint>

<joint name="to_right_wheel" type="continuous">
  <origin xyz="-0.1 -0.095 0.035" rpy="0 0 0"/>
  <parent link="base_link"/>
  <child link="right_wheel_1"/>
  <axis xyz="0.0 1.0 0.0"/>
</joint>

</robot>
